Workbook
Name Avions: Convertisseurs!#REF!
Name Biocombustibles: Convertisseurs!#REF!
Name Carburant: Convertisseurs!#REF!
Name CFC_hors_kyoto: Convertisseurs!#REF!
Name chaussée: Convertisseurs!#REF!
Name Combustibles: Convertisseurs!#REF!
Name CONSOMMABLES_ET_MATERIAUX: 'Campus site 1'!$A$338:$T$468
Name construction_surface: Convertisseurs!#REF!
Name Déchets_carton_annuels: #REF!
Name Déchets_carton_par_jour__kg: #REF!
Name DECHETS_DIRECTS: 'Campus site 1'!$A$608:$T$684
Name Déchets_journeaux_dans_l_année: #REF!
Name Déchets_journeaux_par_jour: #REF!
Name Déchets_papier_du_forum__tonnes: #REF!
Name Déchets_plastiques_annuels: #REF!
Name Déchets_plastiques_par_jour__kg: #REF!
Name Densité_de_l_eau__kg_m3: #REF!
Name DEPLACEMENT_PERSONNES: 'Campus site 1'!$A$206:$S$336
Name Distance_moyenne_en_TGV_longue_distance__km: #REF!
Name Eaux_usées_annuelles__m3: #REF!
Name Effectif_total: #REF!
Name Electricite_m2: Convertisseurs!#REF!
Name Electricite_pays: Convertisseurs!#REF!
Name Electricite_producteur: Convertisseurs!#REF!
Name Extrapolation_personnes_prenant_le_TGV_régulièrement: #REF!
Name FRET: 'Campus site 1'!$A$101:$W$204
Name fret_ferroviaire: Convertisseurs!#REF!
Name fret_fluvial_bassin: Convertisseurs!#REF!
Name fret_fluvial_bateau: Convertisseurs!#REF!
Name fret_maritime: Convertisseurs!#REF!
Name fret_routier: Convertisseurs!#REF!
Name Halocarbures_Kyoto: Convertisseurs!#REF!
Name IMMOBILISATIONS: 'Campus site 1'!$A$685:$T$780
Name INIES: Convertisseurs!#REF!
Name Largeur_feuille__m: #REF!
Name Longueur_feuille__m: #REF!
Name matériaux_construction_batiments: Convertisseurs!#REF!
Name Metaux: Convertisseurs!#REF!
Name métaux: Convertisseurs!#REF!
Name Nombre_de_canettes_par_jour: #REF!
Name Nombre_de_déplacements_par_semaine: #REF!
Name Nombre_de_feuilles_jetées_dans_l_année: #REF!
Name Nombre_de_feuilles_jetées_pour_deux_semaines: #REF!
Name Nombre_de_feuilles_par_ramette: #REF!
Name Nombre_de_jour_par_semaine_sur_le_campus: #REF!
Name Nombre_de_ramettes: #REF!
Name Nombre_de_semaines: #REF!
Name Nombre_de_semaines_sur_le_campus: #REF!
Name Nombre_de_trajets_TGV_longue_distance_par_personne: #REF!
Name Nomrbe_de_répondants: #REF!
Name Papier: Convertisseurs!#REF!
Name personnes_train: '[1]Facteurs d''émission'!$A$452:$A$473
Name plastique: Convertisseurs!#REF!
Name Plastiques: Convertisseurs!#REF!
Name Poids_d_une_canette_vide__g: #REF!
Name Poids_des_feuilles_jetées_dans_l_année__tonnes: #REF!
Name Poids_feuille_par_surface__g_m²: #REF!
Name Pourcentage_de_répondants: #REF!
Name produit_agricole: Convertisseurs!#REF!
Name produit_chimique: Convertisseurs!#REF!

Sheet Accueil
E2: Tableur PCC - Projet Carbone Campus
C5: A quoi sert cet outil ?
C6: Cet outil est utilisé dans le cadre du Projet Carbone Campus pour réaliser le bilan carbone d'un campus. Si quelqu'un vous a transmis ce tableur sans formation préalable, nous vous recommandons de contacter le Réseau Français des Etudiants pour le Développement Durable (REFEDD) : http://refedd.org/projet-carbone-campus/ L’outil permet de comptabiliser les émissions de gaz à effet de serre d'un campus. La finalité de l’outil consiste à introduire la méthode du Bilan Carbone aux étudiants et les assister dans la réalisation d'un plan d'action auprès de la direction de l'établissement et autres parties prenantes. Cet outil n'a pas pour vocation à être utilisé pour un Bilan Carbone® officiel. Pour obtenir le tableur officiel, se rapprocher de l'Association Bilan Carbone (ABC) : https://www.associationbilancarbone.fr/
C10: Comment utiliser cet outil?
C11: L'onglet principal (Campus site) permet : - de renseigner les différentes quantités impactant le campus, sur les différents poste : de "sources fixes" à "immobilisations" - d'en déduire son impact climatique en eq-CO2 - de se fixer des objectifs de réduction d'émissions de GES L'onglet Facteur d'émission permet de vérifier les facteurs d'émissions utilisés dans l'onglet principal et d'en ajouter de nouveaux. L'onglet Totalisateur permet de voir le résultat de son bilan, et poursuivre la démarche itérative. L'onglet Convertisseurs permet de faire quelques conversions d'unités, et d'estimer les fuites de fluides frigorigènes. Une notice détaillée de l'outil est disponible.
B15: Le tableur PCC est à mis à disposition selon les termes de
B16: la licence Creative Commons Attribution 4.0 Internationale
B19: La version de référence de cet outil est disponible sur le site web d'Avenir Climatique.
B21: Pour toute remarque ou question concernant cette outil, merci de nous contacter : contact@avenirclimatique.org

Sheet Facteurs d'émission
B1: Catégorie | C1: Sous catégorie | D1: Source d'émission | E1: Facteur d'émission (eq CO2) | F1: Unité | G1: Incertitude (%) | H1: Dernière mise à jour | I1: Période de validité | J1: Source
B2: SOURCES FIXES | C2: Combustible | D2: Fioul domestique | E2: 0.32 | F2: kgCO2e/kWh PCI | G2: 0.05 | H2: 45644 | I2: 43070 | J2: Base Empreinte ADEME
B3: SOURCES FIXES | C3: Combustible | D3: Fioul lourd | E3: 0.32 | F3: kgCO2e/kWh PCI | G3: 0.05 | H3: 45644 | I3: 43435 | J3: Base Empreinte ADEME
B4: SOURCES FIXES | C4: Combustible | D4: Gaz Naturel | E4: 0.24 | F4: kgCO2e/kWh PCI | G4: 0.05 | H4: 45644 | I4: 45716 | J4: Base Empreinte ADEME
B5: SOURCES FIXES | C5: Combustible | D5: Bois granulé / Combustion en chaudière / Label E+ | E5: 0.027 | F5: kgCO2e/kWh | H5: 45278 | I5: 44166 | J5: Base Empreinte ADEME
B6: SOURCES FIXES | C6: Combustible | D6: A COMPLETER DANS FACTEURS D'EMISSIONS | L6: Pour toute question ou pour trouver de nouveaux facteurs d'émissions :
B7: SOURCES FIXES | C7: Combustible | D7: A COMPLETER DANS FACTEURS D'EMISSIONS
B8: SOURCES FIXES | C8: Combustible | D8: A COMPLETER DANS FACTEURS D'EMISSIONS
B9: SOURCES FIXES | C9: Combustible | D9: A COMPLETER DANS FACTEURS D'EMISSIONS | L9: https://base-empreinte.ademe.fr/
B10: SOURCES FIXES | C10: Combustible | D10: A COMPLETER DANS FACTEURS D'EMISSIONS
B11: SOURCES FIXES | C11: Electricité | D11: Mix électrique français (année 2024) | E11: 0.0519 | F11: kgCO2e/kWh | G11: 0.1 | H11: 45644 | I11: 45627 | J11: Base Empreinte ADEME
B12: SOURCES FIXES | C12: Electricité | D12: Mix électrique français (année 2021) | E12: 0.0569 | F12: kgCO2e/kWh | G12: 0.1 | H12: 44548 | I12: 44531 | J12: Base Empreinte ADEME
B13: SOURCES FIXES | C13: Electricité | D13: Mix électrique français (année 2017) | E13: 0.056 | F13: kgCO2e/kWh | G13: 0.1 | H13: 43087 | I13: 43070 | J13: Base Empreinte ADEME
B14: SOURCES FIXES | C14: Electricité | D14: Mix électrique allemand (année 2017) | E14: 0.46 | F14: kgCO2e/kWh | G14: 0.1 | H14: 43087 | I14: 43070 | J14: Base Empreinte ADEME
B15: SOURCES FIXES | C15: Electricité | D15: Mix électrique européen (année 2017) | E15: 0.42 | F15: kgCO2e/kWh | G15: 0.1 | H15: 43087 | I15: 43070 | J15: Base Empreinte ADEME
B16: SOURCES FIXES | C16: Electricité | D16: A COMPLETER DANS FACTEURS D'EMISSIONS
B17: SOURCES FIXES | C17: Gaz frigorifique | D17: R134a | E17: 1530 | F17: kgCO2e/kg | G17: 0.3 | H17: 45556 | J17: GIEC AR6
B18: SOURCES FIXES | C18: Gaz frigorifique | D18: R22 (gaz interdit à la vente et à l'utilisation depuis 2015) | E18: 1960 | F18: kgCO2e/kg | G18: 0.3 | H18: 45556 | J18: GIEC AR6
B19: SOURCES FIXES | C19: Gaz frigorifique | D19: R32 | E19: 770 | F19: kgCO2e/kg | G19: 0.3 | H19: 45556 | J19: GIEC AR6
B20: SOURCES FIXES | C20: Gaz frigorifique | D20: R404a (gaz interdit à la vente depuis 2020 et à l'utilisation depuis 2025) | E20: 4730 | F20: kgCO2e/kg | G20: 0.3 | H20: 45556 | J20: Base Empreinte ADEME
B21: SOURCES FIXES | C21: Gaz frigorifique | D21: R407c | E21: 1910 | F21: kgCO2e/kg | G21: 0.3 | H21: 45556 | J21: Base Empreinte ADEME
B22: SOURCES FIXES | C22: Gaz frigorifique | D22: R410a | E22: 2260 | F22: kgCO2e/kg | G22: 0.3 | H22: 45556 | J22: Base Empreinte ADEME
B23: SOURCES FIXES | C23: Gaz frigorifique | D23: R427a | E23: 2400 | F23: kgCO2e/kg | G23: 0.3 | H23: 45556 | J23: Base Empreinte ADEME
B24: SOURCES FIXES | C24: Gaz frigorifique | D24: R507a | E24: 2640 | F24: kgCO2e/kg | G24: 0.3 | H24: 45556 | J24: Base Empreinte ADEME
B25: SOURCES FIXES | C25: Gaz frigorifique | D25: A COMPLETER DANS FACTEURS D'EMISSIONS
B26: SOURCES FIXES | C26: Gaz frigorifique | D26: A COMPLETER DANS FACTEURS D'EMISSIONS
B27: SOURCES FIXES | C27: Gaz frigorifique | D27: A COMPLETER DANS FACTEURS D'EMISSIONS
B28: SOURCES FIXES | C28: Gaz frigorifique | D28: A COMPLETER DANS FACTEURS D'EMISSIONS
B29: SOURCES FIXES | C29: Gaz frigorifique | D29: A COMPLETER DANS FACTEURS D'EMISSIONS
B30: FRET | C30: Fret routier | D30: Camion porteur - Diesel avec 7% biodiesel, PTAC 20T | E30: 0.17 | F30: kgCO2e/tonne.km | G30: 0.7 | H30: 46009 | I30: 46357 | J30: Base Empreinte ADEME
B31: FRET | C31: Fret routier | D31: Camion porteur - Diesel avec 7% biodiesel, PTAC 7,5T | E31: 0.4 | F31: kgCO2e/tonne.km | G31: 0.7 | H31: 46009 | I31: 46357 | J31: Base Empreinte ADEME
B32: FRET | C32: Fret routier | D32: Camion porteur - Diesel avec 7% biodiesel, PTRA 26T | E32: 0.14 | F32: kgCO2e/tonne.km | G32: 0.7 | H32: 46009 | I32: 46357 | J32: Base Empreinte ADEME
B33: FRET | C33: Fret routier | D33: Camion porteur - Diesel avec 7% biodiesel, PTRA 40T | E33: 0.087 | F33: kgCO2e/tonne.km | G33: 0.7 | H33: 46009 | I33: 46357 | J33: Base Empreinte ADEME
B34: FRET | C34: Fret routier | D34: Véhicule Utilitaire Léger - Essence | E34: 0.92 | F34: kgCO2e/tonne.km | G34: 0.7 | H34: 46009 | I34: 46357 | J34: Base Empreinte ADEME
B35: FRET | C35: Fret routier | D35: A COMPLETER DANS FACTEURS D'EMISSIONS
B36: FRET | C36: Fret routier | D36: A COMPLETER DANS FACTEURS D'EMISSIONS
B37: FRET | C37: Fret routier | D37: A COMPLETER DANS FACTEURS D'EMISSIONS
B38: FRET | C38: Fret routier | D38: A COMPLETER DANS FACTEURS D'EMISSIONS
B39: FRET | C39: Fret routier | D39: A COMPLETER DANS FACTEURS D'EMISSIONS
B40: FRET | C40: Fret aérien | D40: Avion (marchandises) - plus de 220 sièges, trajet de 1000 - 2000 km avec trainées | E40: 2.36 | F40: kgCO2e/tonne.km | G40: 0.7 | H40: 45914 | I40: 46357 | J40: Base Empreinte ADEME
...

Sheet Campus site 1
C3: EMISSIONS DU SITE CAMPUS 1
C4: Outil développé sur la base de la méthode Bilan Carbone® par AVENIR CLIMATIQUE
C5: SOURCES FIXES | D5: FRET | E5: DEPLACEMENTS DE PERSONNES | F5: CONSOMMABLES ET MATERIAUX | G5: RESTAURANT UNIVERSITAIRE | H5: DECHETS DIRECTS | I5: IMMOBILISATIONS | J5: TOTAL
C7: ATTENTION : lorsque vous entrez une valeur dans une des cases à fond orange, le maintien d'une valeur nulle (0) dans une des cases à fond blanc et police noire ne signifie pas que le résultat est nul, mais simplement que l'arrondi est nul.
C9: SOURCES FIXES
E13: COMBUSTIBLES FOSSILES
C15: Quelles sont les consommations de combustibles fossiles du campus quel qu'en soit l'usage ? | G15: Emissions de CO2 | I15: Incertitude | M15: Objectif de réduction | P15: Action de réduction
C16: Combustible | D16: Consommation (kWh PCI) | E16: kgCO2e/kWh PCI avec amont | G16: kgCO2e | I16: Fact. d'émission (%) | J16: Données (%) | K16: kgCO2e | M16: Objectif (%) | N16: kgCO2e | P16: Action de réduction planifiée :
C17: Gaz Naturel | D17: 3456200 | E17: =_xlfn.IFNA(VLOOKUP($C17,'Facteurs d''émission'!$D$2:$I$340,2,FALSE),"Non présent dans la base") -> 0.24 | G17: =D17*E17 -> 829488 | I17: =_xlfn.IFNA(VLOOKUP($C17,'Facteurs d''émission'!$D$2:$I$340,4,FALSE),"Non présent dans la base") -> 0.05 | K17: =G17*(1-(1-I17)*(1-J17)) -> 41474.4 | L17: =IF(D17*COUNTA(J17)>0,"ok","") | N17: =G17*M17 -> 0 | P17: * * *
C18: Fioul lourd | E18: =_xlfn.IFNA(VLOOKUP($C18,'Facteurs d''émission'!$D$2:$I$340,2,FALSE),"Non renseigné") -> 0.32 | G18: =D18*E18 -> 0 | I18: =_xlfn.IFNA(VLOOKUP($C18,'Facteurs d''émission'!$D$2:$I$340,4,FALSE),"Non présent dans la base") -> 0.05 | K18: =G18*(1-(1-I18)*(1-J18)) -> 0 | L18: =IF(D18*COUNTA(J18)>0,"ok","") | N18: =G18*M18 -> 0
C19: Fioul domestique | E19: =_xlfn.IFNA(VLOOKUP($C19,'Facteurs d''émission'!$D$2:$I$340,2,FALSE),"Non renseigné") -> 0.32 | G19: =D19*E19 -> 0 | I19: =_xlfn.IFNA(VLOOKUP($C19,'Facteurs d''émission'!$D$2:$I$340,4,FALSE),"Non présent dans la base") -> 0.05 | K19: =G19*(1-(1-I19)*(1-J19)) -> 0 | L19: =IF(D19*COUNTA(J19)>0,"ok","") | N19: =G19*M19 -> 0
C20: Bois granulé / Combustion en chaudière / Label E+ | E20: =_xlfn.IFNA(VLOOKUP($C20,'Facteurs d''émission'!$D$2:$I$340,2,FALSE),"Non renseigné") -> 0.027 | G20: =D20*E20 -> 0 | I20: =_xlfn.IFNA(VLOOKUP($C20,'Facteurs d''émission'!$D$2:$I$340,4,FALSE),"Non présent dans la base") -> 0 | K20: =G20*(1-(1-I20)*(1-J20)) -> 0 | L20: =IF(D20*COUNTA(J20)>0,"ok","") | N20: =G20*M20 -> 0
C21: A COMPLETER DANS FACTEURS D'EMISSIONS | E21: =_xlfn.IFNA(VLOOKUP($C21,'Facteurs d''émission'!$D$2:$I$340,2,FALSE),"Non renseigné") -> 0 | G21: =D21*E21 -> 0 | I21: =_xlfn.IFNA(VLOOKUP($C21,'Facteurs d''émission'!$D$2:$I$340,4,FALSE),"Non présent dans la base") -> 0 | K21: =G21*(1-(1-I21)*(1-J21)) -> 0 | L21: =IF(D21*COUNTA(J21)>0,"ok","") | N21: =G21*M21 -> 0
C22: A COMPLETER DANS FACTEURS D'EMISSIONS | E22: =_xlfn.IFNA(VLOOKUP($C22,'Facteurs d''émission'!$D$2:$I$340,2,FALSE),"Non renseigné") -> 0 | G22: =D22*E22 -> 0 | I22: =_xlfn.IFNA(VLOOKUP($C22,'Facteurs d''émission'!$D$2:$I$340,4,FALSE),"Non présent dans la base") -> 0 | K22: =G22*(1-(1-I22)*(1-J22)) -> 0 | L22: =IF(D22*COUNTA(J22)>0,"ok","") | N22: =G22*M22 -> 0
C23: A COMPLETER DANS FACTEURS D'EMISSIONS | E23: =_xlfn.IFNA(VLOOKUP($C23,'Facteurs d''émission'!$D$2:$I$340,2,FALSE),"Non renseigné") -> 0 | G23: =D23*E23 -> 0 | I23: =_xlfn.IFNA(VLOOKUP($C23,'Facteurs d''émission'!$D$2:$I$340,4,FALSE),"Non présent dans la base") -> 0 | K23: =G23*(1-(1-I23)*(1-J23)) -> 0 | L23: =IF(D23*COUNTA(J23)>0,"ok","") | N23: =G23*M23 -> 0
C24: Total | D24: =SUM(D17:D23) -> 3456200 | G24: =SUM(G17:G23) -> 829488 | I24: =IF(COUNTA(D17:D23)>COUNTIF(L17:L23,"ok"),"! Remplir une incertitude !","") -> ! Remplir une incertitude ! | K24: =SUM(K17:K23) -> 41474.4 | N24: =SUM(N17:N23) -> 0 | P24: =IF(N24>0,IF(#REF!="","Attention: vous devez planifier une action afin de remplir votre objectif",""),"")
E28: ELECTRICITE
C30: Quelle est la consommation totale en électricité du campus ? | G30: Emissions de CO2 | I30: Incertitude | M30: Objectif de réduction | P30: Action de réduction
C31: Source | D31: Consommation (kWh) | E31: kgCO2e par kWh | F31: Taux de pertes en ligne | G31: kgCO2e | I31: Fact. d'émission (%) | J31: Données (%) | K31: kgCO2e | M31: Objectif (%) | N31: kgCO2e | P31: Action de réduction planifiée :
C32: Mix électrique français (année 2024) | D32: 2091000 | E32: =_xlfn.IFNA(VLOOKUP($C32,'Facteurs d''émission'!$D$2:$I$340,2,FALSE),"Non renseigné") -> 0.0519 | F32: 0.1 | G32: =D32*E32*(1+F32) -> 119375.19 | I32: =_xlfn.IFNA(VLOOKUP($C32,'Facteurs d''émission'!$D$2:$I$340,4,FALSE),"Non présent dans la base") -> 0.1 | K32: =G32*(1-(1-I32)*(1-J32)) -> 11937.519 | L32: =IF(D32*COUNTA(J32)>0,"ok","") | N32: =G32*M32 -> 0 | P32: * * *
C33: A COMPLETER DANS FACTEURS D'EMISSIONS | E33: =_xlfn.IFNA(VLOOKUP($C33,'Facteurs d''émission'!$D$2:$I$340,2,FALSE),"Non renseigné") -> 0 | G33: =D33*E33*(1+F33) -> 0 | I33: =_xlfn.IFNA(VLOOKUP($C33,'Facteurs d''émission'!$D$2:$I$340,4,FALSE),"Non présent dans la base") -> 0 | K33: =G33*(1-(1-I33)*(1-J33)) -> 0 | L33: =IF(D33*COUNTA(J33)>0,"ok","") | N33: =G33*M33 -> 0
C34: A COMPLETER DANS FACTEURS D'EMISSIONS | E34: =_xlfn.IFNA(VLOOKUP($C34,'Facteurs d''émission'!$D$2:$I$340,2,FALSE),"Non renseigné") -> 0 | G34: =D34*E34*(1+F34) -> 0 | I34: =_xlfn.IFNA(VLOOKUP($C34,'Facteurs d''émission'!$D$2:$I$340,4,FALSE),"Non présent dans la base") -> 0 | K34: =G34*(1-(1-I34)*(1-J34)) -> 0 | L34: =IF(D34*COUNTA(J34)>0,"ok","") | N34: =G34*M34 -> 0
C35: A COMPLETER DANS FACTEURS D'EMISSIONS | E35: =_xlfn.IFNA(VLOOKUP($C35,'Facteurs d''émission'!$D$2:$I$340,2,FALSE),"Non renseigné") -> 0 | G35: =D35*E35*(1+F35) -> 0 | I35: =_xlfn.IFNA(VLOOKUP($C35,'Facteurs d''émission'!$D$2:$I$340,4,FALSE),"Non présent dans la base") -> 0 | K35: =G35*(1-(1-I35)*(1-J35)) -> 0 | L35: =IF(D35*COUNTA(J35)>0,"ok","") | N35: =G35*M35 -> 0
C36: Total | D36: =SUM(D32:D35) -> 2091000 | G36: =SUM(G32:G35) -> 119375.19 | I36: =IF(COUNTA(D32:D35)>COUNTIF(L32:L35,"ok"),"! Remplir une incertitude !","") -> ! Remplir une incertitude ! | K36: =SUM(K32:K35) -> 11937.519 | N36: =SUM(N32:N35) -> 0 | P36: =IF(N36>0,IF(#REF!="","Attention: vous devez planifier une action afin de remplir votre objectif",""),"")
E40: FUITES DE FLUIDES FRIGORIGENES (Climatisation)
C42: Quelles sont les émissions liées aux fuites de gaz frigorigènes (climatisation, chambres froides, etc.) ? | G42: Emissions de CO2 | I42: Incertitude | M42: Objectif de réduction | P42: Action de réduction
C43: Nature du gaz utilisé | D43: kg émis par an | E43: kgCO2e par kg | G43: kgCO2e | I43: Fact. d'émission (%) | J43: Données (%) | K43: kgCO2e | M43: Objectif (%) | N43: kgCO2e | P43: Action de réduction planifiée :
C44: R134a | E44: =_xlfn.IFNA(VLOOKUP($C44,'Facteurs d''émission'!$D$2:$I$340,2,FALSE),"Non renseigné") -> 1530 | G44: =D44*E44 -> 0 | I44: =_xlfn.IFNA(VLOOKUP($C44,'Facteurs d''émission'!$D$2:$I$340,4,FALSE),"Non présent dans la base") -> 0.3 | K44: =G44*(1-(1-I44)*(1-J44)) -> 0 | L44: =IF(D44*COUNTA(J44)>0,"ok","") | N44: =G44*M44 -> 0 | P44: * * *
C45: R407c | E45: =_xlfn.IFNA(VLOOKUP($C45,'Facteurs d''émission'!$D$2:$I$340,2,FALSE),"Non renseigné") -> 1910 | G45: =D45*E45 -> 0 | I45: =_xlfn.IFNA(VLOOKUP($C45,'Facteurs d''émission'!$D$2:$I$340,4,FALSE),"Non présent dans la base") -> 0.3 | K45: =G45*(1-(1-I45)*(1-J45)) -> 0 | L45: =IF(D45*COUNTA(J45)>0,"ok","") | N45: =G45*M45 -> 0
C46: R32 | E46: =_xlfn.IFNA(VLOOKUP($C46,'Facteurs d''émission'!$D$2:$I$340,2,FALSE),"Non renseigné") -> 770 | G46: =D46*E46 -> 0 | I46: =_xlfn.IFNA(VLOOKUP($C46,'Facteurs d''émission'!$D$2:$I$340,4,FALSE),"Non présent dans la base") -> 0.3 | K46: =G46*(1-(1-I46)*(1-J46)) -> 0 | L46: =IF(D46*COUNTA(J46)>0,"ok","") | N46: =G46*M46 -> 0
C47: R410a | D47: 135 | E47: =_xlfn.IFNA(VLOOKUP($C47,'Facteurs d''émission'!$D$2:$I$340,2,FALSE),"Non renseigné") -> 2260 | G47: =D47*E47 -> 305100 | I47: =_xlfn.IFNA(VLOOKUP($C47,'Facteurs d''émission'!$D$2:$I$340,4,FALSE),"Non présent dans la base") -> 0.3 | K47: =G47*(1-(1-I47)*(1-J47)) -> 91530 | L47: =IF(D47*COUNTA(J47)>0,"ok","") | N47: =G47*M47 -> 0
C48: A COMPLETER DANS FACTEURS D'EMISSIONS | E48: =_xlfn.IFNA(VLOOKUP($C48,'Facteurs d''émission'!$D$2:$I$340,2,FALSE),"Non renseigné") -> 0 | G48: =D48*E48 -> 0 | I48: =_xlfn.IFNA(VLOOKUP($C48,'Facteurs d''émission'!$D$2:$I$340,4,FALSE),"Non présent dans la base") -> 0 | K48: =G48*(1-(1-I48)*(1-J48)) -> 0 | L48: =IF(D48*COUNTA(J48)>0,"ok","") | N48: =G48*M48 -> 0
C49: A COMPLETER DANS FACTEURS D'EMISSIONS | E49: =_xlfn.IFNA(VLOOKUP($C49,'Facteurs d''émission'!$D$2:$I$340,2,FALSE),"Non renseigné") -> 0 | G49: =D49*E49 -> 0 | I49: =_xlfn.IFNA(VLOOKUP($C49,'Facteurs d''émission'!$D$2:$I$340,4,FALSE),"Non présent dans la base") -> 0 | K49: =G49*(1-(1-I49)*(1-J49)) -> 0 | L49: =IF(D49*COUNTA(J49)>0,"ok","") | N49: =G49*M49 -> 0
C50: Total | D50: =SUM(D44:D49) -> 135 | G50: =SUM(G44:G49) -> 305100 | I50: =IF(COUNTA(D44:D49)>COUNTIF(L44:L49,"ok"),"! Remplir une incertitude !","") -> ! Remplir une incertitude ! | K50: =SUM(K44:K49) -> 91530 | N50: =SUM(N44:N49) -> 0 | P50: =IF(N50>0,IF(#REF!="","Attention: vous devez planifier une action afin de remplir votre objectif",""),"")
C54: RESULTATS DES SOURCES FIXES
C56: RECAPITULATIF EQUIVALENT CARBONE | E56: Emissions | I56: Incertitude | M56: Objectif de réduction | P56: Résiduel
C57: SOURCES FIXES, Equivalent Carbone | E57: kgCO2e | F57: tCO2e | G57: en % du total | I57: kgCO2e | J57: tCO2e | K57: % | M57: kgCO2e | N57: tCO2e | O57: en % | P57: tCO2e
C58: Combustibles fossiles | E58: =G24 -> 829488 | F58: =E58/1000 -> 829.488 | G58: =IF(F$61=0,"",F58/F$61) -> 0.6614931 | I58: =K24 -> 41474.4 | J58: =I58/1000 -> 41.4744 | K58: =IF(E58=0,"",I58/E58) -> 0.05 | M58: =N24 -> 0 | N58: =M58/1000 -> 0 | O58: =IF($E58=0,"",M58/$E58) -> 0 | P58: =F58-N58 -> 829.488
C59: Electricité | E59: =G36 -> 119375.19 | F59: =E59/1000 -> 119.37519 | G59: =IF(F$61=0,"",F59/F$61) -> 0.095198321 | I59: =K36 -> 11937.519 | J59: =I59/1000 -> 11.937519 | K59: =IF(E59=0,"",I59/E59) -> 0.1 | M59: =N36 -> 0 | N59: =M59/1000 -> 0 | O59: =IF($E59=0,"",M59/$E59) -> 0 | P59: =F59-N59 -> 119.37519
C60: Fuites de fluides frigorigènes | E60: =G50 -> 305100 | F60: =E60/1000 -> 305.1 | G60: =IF(F$61=0,"",F60/F$61) -> 0.24330858 | I60: =K50 -> 91530 | J60: =I60/1000 -> 91.53 | K60: =IF(E60=0,"",I60/E60) -> 0.3 | M60: =N50 -> 0 | N60: =M60/1000 -> 0 | O60: =IF($E60=0,"",M60/$E60) -> 0 | P60: =F60-N60 -> 305.1
...

Sheet Totalisateur
B2: TOTALISATEUR
C4: SITE 1 | D4: SITE 2 | E4: SITE 3
C5: tCO2e | D5: tCO2e | E5: tCO2e
B6: SOURCES FIXES | C6: =SUM(C7:C9) -> 1253.9632 | E6: =SUM(E7:E9) -> 0 | G6: Total des émissions | K6: Total des incertitudes
B7: ='Campus site 1'!C58 -> Combustibles fossiles | C7: ='Campus site 1'!$E58/1000 -> 829.488 | G7: POSTES | H7: tCO2e | I7: % du total | K7: tCO2e | L7: % du total
B8: ='Campus site 1'!C59 -> Electricité | C8: ='Campus site 1'!$E59/1000 -> 119.37519 | G8: Sources fixes | H8: =SUM(C6:E6) -> 1253.9632 | I8: =IF($H$15=0,"",H8/$H$15) -> 0.47025012 | L8: =IFERROR(K8/H8,"") -> 0
B9: ='Campus site 1'!C60 -> Fuites de fluides frigorigènes | C9: ='Campus site 1'!$E60/1000 -> 305.1 | G9: Fret | H9: =SUM(C11:E11) -> 32.752 | I9: =IF($H$15=0,"",H9/$H$15) -> 0.012282364 | L9: =IFERROR(K9/H9,"") -> 0
G10: Déplacements de personnes | H10: =SUM(C17:E17) -> 490.43616 | I10: =IF($H$15=0,"",H10/$H$15) -> 0.18391901 | L10: =IFERROR(K10/H10,"") -> 0
B11: ='Campus site 1'!C103 -> FRET | C11: =SUM(C12:C15) -> 32.752 | E11: =SUM(E12:E15) -> 0 | G11: Consommables et matériaux | H11: =SUM(C23:E23) -> 28.703466 | I11: =IF($H$15=0,"",H11/$H$15) -> 0.010764118 | L11: =IFERROR(K11/H11,"") -> 0
B12: ='Campus site 1'!C164 -> Fret routier | C12: ='Campus site 1'!$F164 -> 32.752 | G12: Restaurant universitaire | H12: =SUM(C31:E31) -> 457.164 | I12: =IF($H$15=0,"",H12/$H$15) -> 0.17144158 | L12: =IFERROR(K12/H12,"") -> 0
B13: ='Campus site 1'!C165 -> Fret aérien | C13: ='Campus site 1'!$F165 -> 0 | G13: Déchêts directs | H13: =SUM(C36:E36) -> 7.223155 | I13: =IF($H$15=0,"",H13/$H$15) -> 0.0027087633 | L13: =IFERROR(K13/H13,"") -> 0
B14: ='Campus site 1'!C166 -> Fret ferroviaire | C14: ='Campus site 1'!$F166 -> 0 | G14: Immobilisations | H14: =SUM(C40:E40) -> 396.34573 | I14: =IF($H$15=0,"",H14/$H$15) -> 0.14863405 | L14: =IFERROR(K14/H14,"") -> 0
B15: ='Campus site 1'!C167 -> Fret maritime | C15: ='Campus site 1'!$F167 -> 0 | G15: TOTAL | H15: =SUM(H8:H14) -> 2666.5877 | I15: =SUM(I8:I14) -> 1 | K15: =SUM(K8:K14) -> 0 | L15: =IF(H15=0,"",K15/H15) -> 0
B17: ='Campus site 1'!C208 -> DEPLACEMENTS DE PERSONNES | C17: =SUM(C18:C21) -> 490.43616 | E17: =SUM(E18:E21) -> 0
B18: ='Campus site 1'!C298 -> Voiture | C18: ='Campus site 1'!$D298/1000 -> 129.3435
B19: ='Campus site 1'!C299 -> Autres modes routiers | C19: ='Campus site 1'!$D299/1000 -> 16.2
B20: ='Campus site 1'!C300 -> Train | C20: ='Campus site 1'!$D300/1000 -> 15.93378
B21: ='Campus site 1'!C301 -> Avion | C21: ='Campus site 1'!$D301/1000 -> 328.95888
B23: ='Campus site 1'!C340 -> CONSOMMABLES ET MATERIAUX | C23: =SUM(C24:C29) -> 28.703466 | E23: =SUM(E24:E29) -> 0
B24: ='Campus site 1'!C427 -> Métaux | C24: ='Campus site 1'!$E427 -> 4.156238
B25: ='Campus site 1'!C428 -> Plastiques | C25: ='Campus site 1'!$E428 -> 0
B26: ='Campus site 1'!C429 -> Verres | C26: ='Campus site 1'!$E429 -> 0
B27: ='Campus site 1'!C430 -> Papiers et cartons | C27: ='Campus site 1'!$E430 -> 18.361728
B28: ='Campus site 1'!C431 -> Produits chimiques & textiles de synthèse | C28: ='Campus site 1'!$E431 -> 0
B29: ='Campus site 1'!C432 -> Autres (produits manufacturés ou services) | C29: ='Campus site 1'!$E432 -> 6.1855
B31: ='Campus site 1'!C471 -> RESTAURANT UNIVERSITAIRE | C31: =SUM(C32:C34) -> 457.164 | E31: =SUM(E32:E34) -> 0
B32: ='Campus site 1'!C566 -> Viandes et poissons | C32: ='Campus site 1'!$D566/1000 -> 0
B33: ='Campus site 1'!C567 -> Autres produits alimentaires | C33: ='Campus site 1'!$D567/1000 -> 0
B34: ='Campus site 1'!C568 -> Repas | C34: ='Campus site 1'!$D568/1000 -> 457.164
B36: ='Campus site 1'!C610 -> DECHETS DIRECTS | C36: =SUM(C37:C38) -> 7.223155 | E36: =SUM(E37:E37) -> 0
B37: ='Campus site 1'!C645 -> Déchets | C37: ='Campus site 1'!$F645 -> 7.138915
B38: Eaux usées | C38: ='Campus site 1'!$F646 -> 0.08424
B40: ='Campus site 1'!C687 -> IMMOBILISATIONS | C40: =SUM(C41:C43) -> 396.34573 | E40: =SUM(E41:E43) -> 0
B41: ='Campus site 1'!C744 -> Bâtiments | C41: ='Campus site 1'!$D744/1000 -> 300.91073
B42: ='Campus site 1'!C745 -> Informatique | C42: ='Campus site 1'!$D745/1000 -> 95.435
B43: ='Campus site 1'!C746 -> Autres équipements | C43: ='Campus site 1'!$G736/1000 -> 0

Sheet Convertisseurs
B2: CONVERTISSEURS ENERGETIQUES
B4: Convertisseur : passage de PCS en PCI
B5: Combustible | C5: kWh PCS | D5: kWh PCI | G5: Combustible | I5: Rapport PCS / PCI
B6: Gaz Naturel | D6: =C6/I6 -> 0 | G6: Gaz naturel | I6: 1.11
B7: GPL | D7: =C7/I7 -> 0 | G7: GPL | I7: 1.09
B8: Essence | D8: =C8/I8 -> 0 | G8: Essence | I8: 1.08
B9: Diesel, fioul domestique | D9: =C9/I9 -> 0 | G9: Diesel, fioul domestique | I9: 1.07
B10: Fioul lourd | D10: =C10/I10 -> 0 | G10: Fioul lourd | I10: 1.06
B11: Charbon | D11: =C11/I11 -> 0 | G11: Charbon | I11: 1.05
B13: Convertisseur : passage de diverses unités physiques vers d'autres unités | M13: conversion des unités
B14: Unité | C14: Valeur | D14: Tep | E14: Tec | F14: Joule | G14: kWh PCI | H14: BTU | I14: m3 de gaz nat. | J14: t bois 20% hum. | M14: tep | N14: tec | O14: Joule | P14: KWh PCI | Q14: BTU | R14: m3 de gaz nat. | S14: tonne bois 20% hum
B15: Tep | D15: =$C15*M15 -> 0 | E15: =$C15*N15 -> 0 | F15: =$C15*O15 -> 0 | G15: =$C15*P15 -> 0 | H15: =$C15*Q15 -> 0 | I15: =$C15*R15 -> 0 | J15: =$C15*S15 -> 0 | L15: tep | M15: 1 | N15: =O15/O16 -> 1.4340344 | O15: 42000000000 | P15: =O15/3600000 -> 11666.667 | Q15: =O15*Q17 -> 39808351 | R15: 1200 | S15: =1/M21 -> 2.991453
B16: Tec | D16: =$C16*M16 -> 0 | E16: =$C16*N16 -> 0 | F16: =$C16*O16 -> 0 | G16: =$C16*P16 -> 0 | H16: =$C16*Q16 -> 0 | I16: =$C16*R16 -> 0 | J16: =$C16*S16 -> 0 | L16: tec | M16: =1/N15 -> 0.69733333 | N16: 1 | O16: =4.184*7000000000 -> 29288000000 | P16: =O16/3600000 -> 8135.5556 | Q16: =O16*Q17 -> 27759690 | R16: =R15/N15 -> 836.8 | S16: =1/N21 -> 2.0860399
B17: Joule | D17: =$C17*M17 -> 0 | E17: =$C17*N17 -> 0 | F17: =$C17*O17 -> 0 | G17: =$C17*P17 -> 0 | H17: =$C17*Q17 -> 0 | I17: =$C17*R17 -> 0 | J17: =$C17*S17 -> 0 | L17: Joule | M17: =1/O15 -> 2.3809524e-11 | N17: =1/O16 -> 3.4143677e-11 | O17: 1 | P17: =1/O18 -> 2.7777778e-07 | Q17: =1/O19 -> 0.00094781789 | R17: =1/O20 -> 2.8571429e-08 | S17: =1/O21 -> 7.1225071e-11
B18: kWh PCI | D18: =$C18*M18 -> 0 | E18: =$C18*N18 -> 0 | F18: =$C18*O18 -> 0 | G18: =$C18*P18 -> 0 | H18: =$C18*Q18 -> 0 | I18: =$C18*R18 -> 0 | J18: =$C18*S18 -> 0 | L18: kwh PCI | M18: =1/P15 -> 8.5714286e-05 | N18: =1/P16 -> 0.00012291724 | O18: 3600000 | P18: 1 | Q18: =1/P19 -> 3412.1444 | R18: =1/P20 -> 0.10285714 | S18: =1/P21 -> 0.00025641026
B19: BTU | D19: =$C19*M19 -> 0 | E19: =$C19*N19 -> 0 | F19: =$C19*O19 -> 0 | G19: =$C19*P19 -> 0 | H19: =$C19*Q19 -> 0 | I19: =$C19*R19 -> 0 | J19: =$C19*S19 -> 0 | L19: BTU | M19: =1/Q15 -> 2.5120357e-08 | N19: =1/Q16 -> 3.6023457e-08 | O19: 1055.055 | P19: =P15*M19 -> 0.00029307083 | Q19: 1 | R19: =1/Q20 -> 3.0144429e-05 | S19: =1/Q21 -> 7.5146368e-08
B20: m3 de Gaz Naturel | D20: =$C20*M20 -> 0 | E20: =$C20*N20 -> 0 | F20: =$C20*O20 -> 0 | G20: =$C20*P20 -> 0 | H20: =$C20*Q20 -> 0 | I20: =$C20*R20 -> 0 | J20: =$C20*S20 -> 0 | L20: m3 de gaz nat. | M20: =1/R15 -> 0.00083333333 | N20: =M20*N15 -> 0.0011950287 | O20: =O15*M20 -> 35000000 | P20: =P15*M20 -> 9.7222222 | Q20: =M20*Q15 -> 33173.626 | R20: 1 | S20: =S19*Q20 -> 0.0024928775
B21: Tonne bois 20% humidité | D21: =$C21*M21 -> 0 | E21: =$C21*N21 -> 0 | F21: =$C21*O21 -> 0 | G21: =$C21*P21 -> 0 | H21: =$C21*Q21 -> 0 | I21: =$C21*R21 -> 0 | J21: =$C21*S21 -> 0 | L21: t bois 20% humidité | M21: =P21/P15 -> 0.33428571 | N21: =P21/P16 -> 0.47937722 | O21: =P21*3600000 -> 14040000000 | P21: 3900 | Q21: =P21*Q18 -> 13307363 | R21: =1/S20 -> 401.14286 | S21: 1
B26: FUITES DE FLUIDE FRIGORIGENES
B28: Fuites : secteur Tertiaire
B29: Equipements | C29: Nombre | D29: Charge moyenne (kg fluide/unité) | E29: Taux de fuite | F29: kg émis par an
B30: Climatisation DRV (bureaux) | C30: 20 | D30: 9 | E30: 0.1 | F30: =C30*D30*E30 -> 18
B31: Climatisation armoire (baie informatique) | C31: 0 | D31: 26 | E31: 0.05 | F31: =C31*D31*E31 -> 0
B32: Climatisation Rooftop (amphi) | C32: 0 | D32: 5 | E32: 0.06 | F32: =C32*D32*E32 -> 0
B33: Autres | C33: 0 | D33: 9 | E33: 0.09 | F33: =C33*D33*E33 -> 0
B36: Fuites : secteur Tertiaire, par puissance d'équipement
B37: Puissance de l'équipement | C37: Surface refroidie (m2) | D37: Conso moyenne (kg fluide/m2) | E37: Taux de fuite | F37: Kg émis par an
B38: P < 50 kW | C38: 0 | D38: 0.3 | E38: 0.1 | F38: =C38*D38*E38 -> 0
B39: 50 < P < 350 kW | C39: 7820 | D39: 0.3 | E39: 0.05 | F39: =C39*D39*E39 -> 117.3
B40: P > 350 kW | C40: 0 | D40: 0.2 | E40: 0.05 | F40: =C40*D40*E40 -> 0
B41: Autres | C41: 0 | D41: 0.3 | E41: 0.04 | F41: =C41*D41*E41 -> 0

Sheet Feuil1
A1: 270650
A2: 240318
A3: 240753
A4: 166595
A5: 161710
A6: 110790
A7: 73553
A8: 53861
A9: 144370
A10: 177046
A11: 211146
A12: 240208
